<?xml version="1.0"?>
<robot xmlns:xacro="http://www.ros.org/wiki/xacro" >
    <xacro:include filename="physical_properties.xacro"/>
    <xacro:include filename="inertial_macros.xacro"/>

    <xacro:macro name="front_left_wheel">

        <link name="front_left_wheel">

            <inertial>
                <origin xyz = "0 0 0"/>
                <mass value="0.4"/>
                <inertia ixx="0.000239" ixy="0.0" ixz="0.0"
                        iyy="0.000239" iyz="0.0"
                        izz="0.000044" />
            </inertial>

            <visual>
                <!-- En rviz el eje X es el rojo, el Y el verde y el Z el azul -->
                <!-- Necesito seguir ajustando más fino basándome en el cilindro de colisiones -->
                <origin xyz="0.2543 -0.02958 -0.169" rpy="-${pi/2} 0 0"/>
                <geometry>
                    <mesh scale="0.001 0.001 0.001" filename="package://simple_rona_robot/meshes/front_left_wheel.stl"/>
                </geometry>
            </visual>

            <collision>
                <origin xyz="0 0 0" rpy="0 0 0"/>
                <geometry>
                    <cylinder radius="0.0375" length="0.05"/>
                </geometry>
            </collision>
            <!-- <xacro:roller_inertial mass="${mass}"/>     -->
        </link>

        <joint name="front_left_wheel_joint" type="continuous">
            <parent link="chassis"/>
            <child link="front_left_wheel"/>
            <origin xyz="${wheel_offset_x} ${wheel_offset_y} ${wheel_offset_z}" rpy="-${pi/2} 0 0"/>
            <axis xyz="0 0 1"/>
        </joint>
    </xacro:macro>
    
</robot>