<?xml version="1.0"?>
<robot xmlns:xacro="http://www.ros.org/wiki/xacro" >
    <xacro:include filename="physical_properties.xacro"/>
    <xacro:include filename="inertial_macros.xacro"/>

    <xacro:macro name="wheel" params="prefix suffix radius length mass offset_x offset_y offset_z wheel_roller_orientation">
        <link name="${prefix}_${suffix}_wheel">
            <visual>
                <origin xyz="0 0 0" rpy="0 0 0"/>
                <geometry>
                    <cylinder radius="${radius}" length="${length}"/>
                </geometry>
                <material name="orange"/>
            </visual>
            <collision>
                <origin xyz="0 0 0" rpy="0 0 0"/>
                <geometry>
                    <cylinder radius="${radius}" length="${length}"/>
                </geometry>
            </collision>
            <!-- <xacro:roller_inertial mass="${mass}"/>     -->
        </link>

        <joint name="${prefix}_${suffix}_wheel_joint" type="continuous">
            <parent link="chassis"/>
            <child link="${prefix}_${suffix}_wheel"/>
            <origin xyz="${offset_x} ${offset_y} ${offset_z}" rpy="-${pi/2} 0 0"/>
            <axis xyz="0 0 1"/>
        </joint>

        <xacro:roller prefix="${prefix}_${suffix}" suffix="one" theta="${2*pi*(1/10)}" roller_orientation="${wheel_roller_orientation}"/>
        <xacro:roller prefix="${prefix}_${suffix}" suffix="two" theta="${2*pi*(2/10)}" roller_orientation="${wheel_roller_orientation}"/>
        <xacro:roller prefix="${prefix}_${suffix}" suffix="thr" theta="${2*pi*(3/10)}" roller_orientation="${wheel_roller_orientation}"/>
        <xacro:roller prefix="${prefix}_${suffix}" suffix="for" theta="${2*pi*(4/10)}" roller_orientation="${wheel_roller_orientation}"/>
        <xacro:roller prefix="${prefix}_${suffix}" suffix="fve" theta="${2*pi*(5/10)}" roller_orientation="${wheel_roller_orientation}"/>
        <xacro:roller prefix="${prefix}_${suffix}" suffix="six" theta="${2*pi*(6/10)}" roller_orientation="${wheel_roller_orientation}"/>
        <xacro:roller prefix="${prefix}_${suffix}" suffix="svn" theta="${2*pi*(7/10)}" roller_orientation="${wheel_roller_orientation}"/>
        <xacro:roller prefix="${prefix}_${suffix}" suffix="ate" theta="${2*pi*(8/10)}" roller_orientation="${wheel_roller_orientation}"/>
        <xacro:roller prefix="${prefix}_${suffix}" suffix="nne" theta="${2*pi*(9/10)}" roller_orientation="${wheel_roller_orientation}"/>
        <xacro:roller prefix="${prefix}_${suffix}" suffix="ten" theta="${2*pi*(10/10)}" roller_orientation="${wheel_roller_orientation}"/>
    </xacro:macro>

</robot>